Workbook

Sheet How to use
A1: Upload test pack: drop each file into the POC as it is
A2: 48 files, one use case each. Nothing to edit: drag a file onto the upload box and compare what the POC shows with this workbook.
A4: 1-Prospecting (P01-P22): drop each file on the Prospecting upload box. Compare the check pane and the final list with "Prospecting rows" and "Prospecting accounts".
A5: 2-Account-Scoring (S01-S07) and 3-Signal-rules (G01-G14): these all use one prospect list, S00.
A6: Once: Account Scoring > New scoring > 1 · Prospect list > "Upload a prospect file" > drop S00_prospect_list_for_scoring_and_signals.csv. It is saved as a list.
A7: Then for each S or G file: choose that S00 list, set "Score as of" to 2026-10-20, and drop the file on box 2. Compare with "Signal rows" and "Scoring accounts".
A8: S01 is also scored on two later dates (shown in the "Score as of" column) to see signals fade.
A9: 4-Micro-segments-and-Review (N01-N04): each file holds a "Lead template" and a "Signal template" sheet. Upload it as the prospect list, then drop the same file as the signals; then send the scoring to Micro-segments & NBA and open For Review.
A10: Their per-account answer keys are in ../poc-test-sets (TS6, TS8, TS9, TS10).
A12: Always set Score as of to 2026-10-20 unless the row gives another date: signal ages are counted from that date.
A13: Mark each file Pass, Fail, Blocked or Not in scope in "Files" (and row by row if you want). For every Fail, add a row to the Gap Log and put its ID in "Gap ID".
A14: Rows marked "known gap" or "SHOULD" describe what the business would expect; the POC does something else today. They are expected to fail until fixed.
... A17: All companies, people and domains are invented.

Sheet Files
A1: ID | B1: Folder | C1: File | D1: Use case | E1: Why it matters | F1: How to run it | G1: Score as of | H1: What you should see | I1: Exact counts (from the POC rules) | J1: Status | K1: What actually happened | L1: Gap ID
A2: P01 | B2: 1-Prospecting | C2: P01_clean_list.xlsx | D2: A clean list | E2: The happy path: every row is fine, so nothing is flagged. | F2: Prospecting: drop P01_clean_list.xlsx on the upload box. | G2: n/a | H2: 15 rows read, 0 issues, 5 accounts, all 5 pass, 15 contacts in the final list. | I2: 15 rows read; 0 not loaded; 0 merged; 5 accounts, 5 pass; 15 in the final list. Issues: 0 stop, 0 flagged, 0 notes. | J2: Not run
A3: P02 | B3: 1-Prospecting | C3: P02_email_problems.xlsx | D3: Email problems | E3: Each row has one thing wrong (or nearly wrong) with the email or its verified flag. | F3: Prospecting: drop P02_email_problems.xlsx on the upload box. | G3: n/a | H3: Malformed emails and a non Y/N verified flag are flagged (D3); unverified emails are noted but not used to send. | I3: 12 rows read; 0 not loaded; 0 merged; 1 accounts, 1 pass; 10 in the final list. Issues: 0 stop, 5 flagged, 5 notes. | J3: Not run
A4: P03 | B4: 1-Prospecting | C4: P03_linkedin_and_no_contact_details.xlsx | D4: LinkedIn problems and missing contact details | E4: LinkedIn URL forms, and rows with no way to contact the person. | F4: Prospecting: drop P03_linkedin_and_no_contact_details.xlsx on the upload box. | G4: n/a | H4: Bad LinkedIn URLs and rows with neither email nor LinkedIn are flagged (D3); the others load. | I4: 8 rows read; 0 not loaded; 0 merged; 1 accounts, 1 pass; 7 in the final list. Issues: 0 stop, 3 flagged, 1 notes. | J4: Not run
A5: P04 | B5: 1-Prospecting | C5: P04_duplicates.xlsx | D5: Duplicate contacts | E5: The same person twice, written differently. Duplicates are merged into the first row. | F5: Prospecting: drop P04_duplicates.xlsx on the upload box. | G5: n/a | H5: 6 rows read, 3 merged as duplicates (D5), 3 contacts left. | I5: 6 rows read; 0 not loaded; 3 merged; 1 accounts, 1 pass; 3 in the final list. Issues: 0 stop, 3 flagged, 4 notes. | J5: Not run
A6: P05 | B6: 1-Prospecting | C6: P05_consent_and_opt_out.xlsx | D6: Consent and opt-out | E6: Every consent basis and opt-out value, and an account where everyone opted out. | F6: Prospecting: drop P05_consent_and_opt_out.xlsx on the upload box. | G6: n/a | H6: Fairway passes with 4 contactable; Glenrock Refining is excluded (no contacts left after suppression). | I6: 12 rows read; 0 not loaded; 0 merged; 2 accounts, 1 pass; 4 in the final list. Issues: 0 stop, 4 flagged, 4 notes. | J6: Not run
A7: P06 | B7: 1-Prospecting | C7: P06_region.xlsx | D7: Pilot region | E7: One company per country spelling. Only the six pilot countries pass; names are matched exactly (case does not matter). | F7: Prospecting: drop P06_region.xlsx on the upload box. | G7: n/a | H7: 11 accounts: 8 pass, 3 excluded (SG, Australia, no country). | I7: 11 rows read; 0 not loaded; 0 merged; 11 accounts, 8 pass; 8 in the final list. Issues: 0 stop, 1 flagged, 0 notes. | J7: Not run
A8: P07 | B8: 1-Prospecting | C8: P07_managed_separately_and_existing_customer.xlsx | D8: Managed separately and existing customer | E8: The two Y/N company flags with every kind of value. | F8: Prospecting: drop P07_managed_separately_and_existing_customer.xlsx on the upload box. | G8: n/a | H8: Anchor Refining excluded (managed separately); the other 7 pass; blank and invalid flags are flagged D3. | I8: 8 rows read; 0 not loaded; 0 merged; 8 accounts, 7 pass; 7 in the final list. Issues: 0 stop, 4 flagged, 0 notes. | J8: Not run
A9: P08 | B9: 1-Prospecting | C9: P08_company_size_formats.xlsx | D9: Company size formats | E9: Revenue and headcount written in different ways. One company per row. | F9: Prospecting: drop P08_company_size_formats.xlsx on the upload box. | G9: n/a | H9: All 9 load; commas, symbols and text in size columns are flagged D3 with what was read. | I9: 9 rows read; 0 not loaded; 0 merged; 9 accounts, 9 pass; 9 in the final list. Issues: 0 stop, 8 flagged, 0 notes. | J9: Not run
A10: P09 | B10: 1-Prospecting | C10: P09_account_types.xlsx | D10: Account types | E10: Each account type on the list, plus blank and one not on the list. | F10: Prospecting: drop P09_account_types.xlsx on the upload box. | G10: n/a | H10: All 8 load; "Trader" is flagged D3; blank is a note. | I10: 8 rows read; 0 not loaded; 0 merged; 8 accounts, 8 pass; 8 in the final list. Issues: 0 stop, 1 flagged, 1 notes. | J10: Not run
A11: P10 | B11: 1-Prospecting | C11: P10_industry_classification.xlsx | D11: Industry and site classification | E11: How each industry and site process maps to a vertical (core, adjacent or other). | F11: Prospecting: drop P10_industry_classification.xlsx on the upload box. | G11: n/a | H11: All 8 load; Echo Water and Halo Chemicals are held for review as Other; Flint Energy is flagged for no industry. | I11: 8 rows read; 0 not loaded; 0 merged; 8 accounts, 8 pass; 8 in the final list. Issues: 0 stop, 1 flagged, 0 notes. | J11: Not run
A12: P11 | B12: 1-Prospecting | C12: P11_job_titles_and_persona.xlsx | D12: Job titles and persona | E12: Which job titles count as the primary persona (the buyer), secondary, or none. | F12: Prospecting: drop P11_job_titles_and_persona.xlsx on the upload box. | G12: n/a | H12: All 15 load in one account; 6 primary, 6 secondary, 3 none; the blank title is flagged. | I12: 15 rows read; 0 not loaded; 0 merged; 1 accounts, 1 pass; 15 in the final list. Issues: 0 stop, 1 flagged, 0 notes. | J12: Not run
A13: P12 | B13: 1-Prospecting | C13: P12_owner_rep.xlsx | D13: Owner rep | E13: The owner_email column: who the account belongs to. | F13: Prospecting: drop P12_owner_rep.xlsx on the upload box. | G13: n/a | H13: All 6 load; blank and invalid owners are flagged D3. | I13: 6 rows read; 0 not loaded; 0 merged; 6 accounts, 6 pass; 6 in the final list. Issues: 0 stop, 3 flagged, 0 notes. | J13: Not run
... A49: N04 | B49: 4-Micro-segments-and-Review | C49: N04_rep_ownership.xlsx | D49: Rep ownership and visibility | E49: Who sees which item: the demo Sales rep role is Rep A (rep.a@client-sample.com) and the Sales manager sees everyone. Owners for Rep A, Rep B, no owner, an owner who is not a user, an owner in capitals, and an owner that is not an email. | F49: Account Scoring: "Upload a prospect file" = N04_rep_ownership.xlsx (reads its "Lead template" sheet); Score as of 2026-10-20; drop the same file on box 2 (reads "Signal template"). Then send to Micro-segments & NBA and open For Review. | G49: 2026-10-20 | H49: As in TS10 (answer key in ../poc-test-sets). | I49: Tiers: A 5, B 4. Segments: Inquiry 5, Engagement 4; 0 exception(s). | J49: Not run

Sheet Prospecting rows
A1: File | B1: Row | C1: What the row tests | D1: Expected flags (field: code issue) | E1: Expected notes | F1: Expected contact status | G1: Persona | H1: Reachable by | I1: Status | J1: What actually happened
A2: P01 | B2: 2 | C2: Primary persona, verified email and LinkedIn | D2: None | F2: In the final list | G2: Primary | H2: email and LinkedIn | I2: Not run
A3: P01 | B3: 3 | C3: Secondary persona | D3: None | F3: In the final list | G3: Secondary | H3: email and LinkedIn | I3: Not run
A4: P01 | B4: 4 | C4: No persona (still in the list) | D4: None | F4: In the final list | G4: None | H4: email and LinkedIn | I4: Not run
A5: P01 | B5: 5 | C5: Primary persona, verified email and LinkedIn | D5: None | F5: In the final list | G5: Primary | H5: email and LinkedIn | I5: Not run
A6: P01 | B6: 6 | C6: Secondary persona | D6: None | F6: In the final list | G6: Secondary | H6: email and LinkedIn | I6: Not run
A7: P01 | B7: 7 | C7: No persona (still in the list) | D7: None | F7: In the final list | G7: None | H7: email and LinkedIn | I7: Not run
A8: P01 | B8: 8 | C8: Primary persona, verified email and LinkedIn | D8: None | F8: In the final list | G8: Primary | H8: email and LinkedIn | I8: Not run
A9: P01 | B9: 9 | C9: Secondary persona | D9: None | F9: In the final list | G9: Secondary | H9: email and LinkedIn | I9: Not run
A10: P01 | B10: 10 | C10: No persona (still in the list) | D10: None | F10: In the final list | G10: None | H10: email and LinkedIn | I10: Not run
A11: P01 | B11: 11 | C11: Primary persona, verified email and LinkedIn | D11: None | F11: In the final list | G11: Primary | H11: email and LinkedIn | I11: Not run
A12: P01 | B12: 12 | C12: Secondary persona | D12: None | F12: In the final list | G12: Secondary | H12: email and LinkedIn | I12: Not run
A13: P01 | B13: 13 | C13: No persona (still in the list) | D13: None | F13: In the final list | G13: None | H13: email and LinkedIn | I13: Not run
... A20: P02 | B20: 5 | C20: Two @ signs: malformed | D20: email: D3 Email "joanne.sim@@coralbayrefining.example" is malformed | F20: In the final list | G20: Primary | H20: LinkedIn | I20: Not run
A21: P02 | B21: 6 | C21: Clean email, no LinkedIn: email only | D21: None | E21: linkedin_url: No LinkedIn URL | F21: In the final list | G21: Primary | H21: email | I21: Not run
A22: P02 | B22: 7 | C22: Email in capitals: accepted and read in lower case | D22: None | F22: In the final list | G22: Primary | H22: email and LinkedIn | I22: Not run
A23: P02 | B23: 8 | C23: Verified written TRUE instead of Y: flagged, email treated as not verified | D23: email_verified: D3 "TRUE" isn't Y or N | F23: In the final list | G23: Primary | H23: LinkedIn | I23: Not run
A24: P02 | B24: 9 | C24: Verified written "yes": accepted as Y | D24: None | F24: In the final list | G24: Primary | H24: email and LinkedIn | I24: Not run
A25: P02 | B25: 10 | C25: Not verified: loaded, email not used; reached by LinkedIn | D25: None | E25: email_verified: Email not verified | F25: In the final list | G25: Primary | H25: LinkedIn | I25: Not run
A26: P02 | B26: 11 | C26: Verified left blank: treated as not verified | D26: None | E26: email_verified: Email not verified | F26: In the final list | G26: Primary | H26: LinkedIn | I26: Not run
A27: P02 | B27: 12 | C27: Malformed email and no LinkedIn: no way to reach them | D27: email: D3 Email "omar.aziz@coralbay" is malformed | F27: In the list, not contactable (no usable email or LinkedIn) | G27: Primary | H27: none | I27: Not run
A28: P02 | B28: 13 | C28: Not verified and no LinkedIn: not contactable | D28: None | E28: email_verified: Email not verified linkedin_url: No LinkedIn URL | F28: In the list, not contactable (no usable email or LinkedIn) | G28: Primary | H28: none | I28: Not run
A29: P03 | B29: 2 | C29: Control: clean | D29: None | F29: In the final list | G29: Primary | H29: email and LinkedIn | I29: Not run
A30: P03 | B30: 3 | C30: Company page, not a person: flagged, LinkedIn not used | D30: linkedin_url: D3 LinkedIn URL "https://www.linkedin.com/company/delta-refining" isn't a profile URL | F30: In the final list | G30: Primary | H30: email | I30: Not run
A31: P03 | B31: 4 | C31: Not a LinkedIn URL: flagged | D31: linkedin_url: D3 LinkedIn URL "www.facebook.com/huimin" isn't a profile URL | F31: In the final list | G31: Primary | H31: email | I31: Not run
A32: P03 | B32: 5 | C32: No https:// or www: accepted | D32: None | F32: In the final list | G32: Primary | H32: email and LinkedIn | I32: Not run
A33: P03 | B33: 6 | C33: Trailing slash: accepted | D33: None | F33: In the final list | G33: Primary | H33: email and LinkedIn | I33: Not run
A34: P03 | B34: 7 | C34: Old /pub/ profile URL: accepted | D34: None | F34: In the final list | G34: Primary | H34: email and LinkedIn | I34: Not run
A35: P03 | B35: 8 | C35: No email, LinkedIn only: reached on LinkedIn | D35: None | E35: email: No email | F35: In the final list | G35: Primary | H35: LinkedIn | I35: Not run
A36: P03 | B36: 9 | C36: No email and no LinkedIn: flagged, kept on the account, not contactable | D36: email / linkedin_url: D3 No email and no LinkedIn URL | F36: In the list, not contactable (no usable email or LinkedIn) | G36: Primary | H36: none | I36: Not run
A37: P04 | B37: 2 | C37: First row for Grace Teh (no LinkedIn) | D37: None | E37: linkedin_url: No LinkedIn URL | F37: In the final list | G37: Primary | H37: email and LinkedIn | I37: Not run
A38: P04 | B38: 3 | C38: Same email in capitals: merged into the row above; its LinkedIn fills the blank | D38: email: D5 Duplicate of row 2 (Grace Teh) | F38: Merged into an earlier row | I38: Not run
A39: P04 | B39: 4 | C39: First row for Ivan Lo | D39: None | F39: In the final list | G39: Primary | H39: email and LinkedIn | I39: Not run
A40: P04 | B40: 5 | C40: Same LinkedIn profile, different URL form, no email: merged | D40: linkedin_url: D5 Duplicate of row 4 (Ivan Lo) | E40: email: No email | F40: Merged into an earlier row | I40: Not run
A41: P04 | B41: 6 | C41: Same name, different email, no LinkedIn: a different contact, not merged | D41: None | E41: linkedin_url: No LinkedIn URL | F41: In the final list | G41: Primary | H41: email | I41: Not run
A42: P04 | B42: 7 | C42: Another company's row reusing Grace Teh's email: merged into her (worth a look) | D42: email: D5 Duplicate of row 2 (Grace Teh) | E42: linkedin_url: No LinkedIn URL | F42: Merged into an earlier row | I42: Not run
A43: P05 | B43: 2 | C43: legitimate interest: contactable | D43: None | F43: In the final list | G43: Primary | H43: email and LinkedIn | I43: Not run
A44: P05 | B44: 3 | C44: existing customer: contactable | D44: None | F44: In the final list | G44: Primary | H44: email and LinkedIn | I44: Not run
A45: P05 | B45: 4 | C45: opted in: contactable | D45: None | F45: In the final list | G45: Primary | H45: email and LinkedIn | I45: Not run
A46: P05 | B46: 5 | C46: Capitalised basis: accepted | D46: None | F46: In the final list | G46: Primary | H46: email and LinkedIn | I46: Not run
...

Sheet Prospecting accounts
A1: File | B1: Account | C1: Region and suppression checks | D1: Vertical | E1: Classification confidence | F1: Held for review | G1: Owner
A2: P01 | B2: Harbour Refining | C2: Passes | D2: Refining (core) | E2: high | F2: No | G2: rep.a@client-sample.com
A3: P01 | B3: Kestrel Petrochem | C3: Passes | D3: Petrochemicals (adjacent) | E3: medium | F3: No | G3: rep.a@client-sample.com
A4: P01 | B4: Selatan LNG | C4: Passes | D4: Gas processing (adjacent) | E4: high | F4: No | G4: rep.b@client-sample.com
A5: P01 | B5: Mekong Refining | C5: Passes | D5: Refining (core) | E5: high | F5: No | G5: rep.b@client-sample.com
A6: P01 | B6: Visayas Gas | C6: Passes | D6: Gas processing (adjacent) | E6: high | F6: No | G6: rep.a@client-sample.com
A7: P02 | B7: Coral Bay Refining | C7: Passes | D7: Refining (core) | E7: high | F7: No | G7: rep.a@client-sample.com
A8: P03 | B8: Delta Refining | C8: Passes | D8: Refining (core) | E8: high | F8: No | G8: rep.a@client-sample.com
A9: P04 | B9: Eastwind Refining | C9: Passes | D9: Refining (core) | E9: high | F9: No | G9: rep.a@client-sample.com
A10: P05 | B10: Fairway Refining | C10: Passes | D10: Refining (core) | E10: high | F10: No | G10: rep.a@client-sample.com
A11: P05 | B11: Glenrock Refining | C11: Excluded: No contactable contacts after suppression | D11: Refining (core) | E11: high | F11: No | G11: rep.a@client-sample.com
A12: P06 | B12: Jurong Fuels | C12: Passes | D12: Refining (core) | E12: high | F12: No | G12: rep.a@client-sample.com
... A87: S00 | B87: Tidewater Refining | C87: Excluded: Outside the pilot region (Australia) | D87: Refining (core) | E87: high | F87: No | G87: rep.a@client-sample.com

Sheet Signal rows
A1: File | B1: Score as of | C1: Row | D1: Company | E1: Type of signal | F1: What the row tests | G1: Expected status | H1: Code | I1: Reason, or who it was given to | J1: Person | K1: Age (days) | L1: Weight | M1: Status | N1: What actually happened
A2: S01 | B2: 2026-10-20 | C2: 2 | D2: Apex Refining | E2: Inquiry or RFQ | F2: Apex: fresh inquiry: tier A | G2: Qualified | H2: Y2 | I2: Named in the file | J2: Kai Ong | K2: 5 | L2: 100 | M2: Not run
A3: S01 | B3: 2026-10-20 | C3: 3 | D3: Bayfront Refining | E3: Installed system near end of support | F3: Bayfront: end of support: tier A | G3: Qualified | H3: Y1 | I3: Named in the file | J3: Mia Tan | K3: 120 | L3: 100 | M3: Not run
A4: S01 | B4: 2026-10-20 | C4: 4 | D4: Coldwater Refining | E4: Capital project | F4: Coldwater: capital project (weight 80): tier A | G4: Qualified | H4: Y4 | I4: Named in the file | J4: Oli Ng | K4: 40 | L4: 80 | M4: Not run
A5: S01 | B5: 2026-10-20 | C5: 5 | D5: Driftwood Refining | E5: Webinar attended | F5: Driftwood: webinar: tier B | G5: Qualified | H5: C1w | I5: Named in the file | J5: Quin Ong | K5: 10 | L5: 60 | M5: Not run
A6: S01 | B6: 2026-10-20 | C6: 6 | D6: Eastgate Refining | E6: Email clicked | F6: Eastgate: one email click: tier C | G6: Qualified | H6: C1x | I6: Named in the file | J6: Sam Sim | K6: 5 | L6: 30 | M6: Not run
A7: S01 | B7: 2026-10-20 | C7: 7 | D7: Moorland Refining | E7: Service contract renewal | F7: Moorland: service renewal | G7: Qualified | H7: Y1 | I7: Named in the file | J7: Wes Goh | K7: 30 | L7: 60 | M7: Not run
A8: S01 | B8: 2026-10-20 | C8: 8 | D8: Newhaven Petrochem | E8: Leadership change | F8: Newhaven: leadership change | G8: Qualified | H8: C1c | I8: Named in the file | J8: Yan Lee | K8: 10 | L8: 45 | M8: Not run
A9: S01 | B9: 2026-10-20 | C9: 9 | D9: Juniper Fuels | E9: Inquiry or RFQ | F9: Juniper (fit 50): inquiry | G9: Qualified | H9: Y2 | I9: Named in the file | J9: Cal Ho | K9: 5 | L9: 100 | M9: Not run
A10: S01 | B10: 2026-10-20 | C10: 10 | D10: Kingsbridge Fuels | E10: Inquiry or RFQ | F10: Kingsbridge (fit 49): qualified but not used, below the fit floor | G10: Not used | H10: Y2 | I10: Qualified, but the account is below the fit floor | J10: Dee Lim | K10: 5 | L10: 100 | M10: Not run
A11: S01 | B11: 2026-10-20 | C11: 11 | D11: Tidewater Refining | E11: Inquiry or RFQ | F11: Tidewater (excluded): qualified but not used | G11: Not used | H11: Y2 | I11: Qualified, but the account is excluded (Outside the pilot region (Australia)) | J11: Hu Koh | K11: 5 | L11: 100 | M11: Not run
A12: S01 | B12: 2026-12-20 | C12: 2 | D12: Apex Refining | E12: Inquiry or RFQ | F12: Apex: fresh inquiry: tier A | G12: Qualified | H12: Y2 | I12: Named in the file | J12: Kai Ong | K12: 66 | L12: 40 | M12: Not run
A13: S01 | B13: 2026-12-20 | C13: 3 | D13: Bayfront Refining | E13: Installed system near end of support | F13: Bayfront: end of support: tier A | G13: Qualified | H13: Y1 | I13: Named in the file | J13: Mia Tan | K13: 181 | L13: 100 | M13: Not run
... A15: S01 | B15: 2026-12-20 | C15: 5 | D15: Driftwood Refining | E15: Webinar attended | F15: Driftwood: webinar: tier B | G15: Qualified | H15: C1w | I15: Named in the file | J15: Quin Ong | K15: 71 | L15: 43.6 | M15: Not run
A16: S01 | B16: 2026-12-20 | C16: 6 | D16: Eastgate Refining | E16: Email clicked | F16: Eastgate: one email click: tier C | G16: Rejected | H16: D2 | I16: 66 days old; this signal type counts for 60 days | J16: Sam Sim | K16: 66 | M16: Not run
A17: S01 | B17: 2026-12-20 | C17: 7 | D17: Moorland Refining | E17: Service contract renewal | F17: Moorland: service renewal | G17: Qualified | H17: Y1 | I17: Named in the file | J17: Wes Goh | K17: 91 | L17: 59.3 | M17: Not run
A18: S01 | B18: 2026-12-20 | C18: 8 | D18: Newhaven Petrochem | E18: Leadership change | F18: Newhaven: leadership change | G18: Qualified | H18: C1c | I18: Named in the file | J18: Yan Lee | K18: 71 | L18: 24.5 | M18: Not run
A19: S01 | B19: 2026-12-20 | C19: 9 | D19: Juniper Fuels | E19: Inquiry or RFQ | F19: Juniper (fit 50): inquiry | G19: Qualified | H19: Y2 | I19: Named in the file | J19: Cal Ho | K19: 66 | L19: 40 | M19: Not run
A20: S01 | B20: 2026-12-20 | C20: 10 | D20: Kingsbridge Fuels | E20: Inquiry or RFQ | F20: Kingsbridge (fit 49): qualified but not used, below the fit floor | G20: Not used | H20: Y2 | I20: Qualified, but the account is below the fit floor | J20: Dee Lim | K20: 66 | L20: 40 | M20: Not run
A21: S01 | B21: 2026-12-20 | C21: 11 | D21: Tidewater Refining | E21: Inquiry or RFQ | F21: Tidewater (excluded): qualified but not used | G21: Not used | H21: Y2 | I21: Qualified, but the account is excluded (Outside the pilot region (Australia)) | J21: Hu Koh | K21: 66 | L21: 40 | M21: Not run
A22: S01 | B22: 2027-04-20 | C22: 2 | D22: Apex Refining | E22: Inquiry or RFQ | F22: Apex: fresh inquiry: tier A | G22: Rejected | H22: D2 | I22: 187 days old; this signal type counts for 90 days | J22: Kai Ong | K22: 187 | M22: Not run
A23: S01 | B23: 2027-04-20 | C23: 3 | D23: Bayfront Refining | E23: Installed system near end of support | F23: Bayfront: end of support: tier A | G23: Qualified | H23: Y1 | I23: Named in the file | J23: Mia Tan | K23: 302 | L23: 100 | M23: Not run
A24: S01 | B24: 2027-04-20 | C24: 4 | D24: Coldwater Refining | E24: Capital project | F24: Coldwater: capital project (weight 80): tier A | G24: Qualified | H24: Y4 | I24: Named in the file | J24: Oli Ng | K24: 222 | L24: 41.6 | M24: Not run
A25: S01 | B25: 2027-04-20 | C25: 5 | D25: Driftwood Refining | E25: Webinar attended | F25: Driftwood: webinar: tier B | G25: Rejected | H25: D2 | I25: 192 days old; this signal type counts for 180 days | J25: Quin Ong | K25: 192 | M25: Not run
A26: S01 | B26: 2027-04-20 | C26: 6 | D26: Eastgate Refining | E26: Email clicked | F26: Eastgate: one email click: tier C | G26: Rejected | H26: D2 | I26: 187 days old; this signal type counts for 60 days | J26: Sam Sim | K26: 187 | M26: Not run
A27: S01 | B27: 2027-04-20 | C27: 7 | D27: Moorland Refining | E27: Service contract renewal | F27: Moorland: service renewal | G27: Rejected | H27: D2 | I27: 212 days old; this signal type counts for 180 days | J27: Wes Goh | K27: 212 | M27: Not run
A28: S01 | B28: 2027-04-20 | C28: 8 | D28: Newhaven Petrochem | E28: Leadership change | F28: Newhaven: leadership change | G28: Rejected | H28: D2 | I28: 192 days old; this signal type counts for 120 days | J28: Yan Lee | K28: 192 | M28: Not run
A29: S01 | B29: 2027-04-20 | C29: 9 | D29: Juniper Fuels | E29: Inquiry or RFQ | F29: Juniper (fit 50): inquiry | G29: Rejected | H29: D2 | I29: 187 days old; this signal type counts for 90 days | J29: Cal Ho | K29: 187 | M29: Not run
A30: S01 | B30: 2027-04-20 | C30: 10 | D30: Kingsbridge Fuels | E30: Inquiry or RFQ | F30: Kingsbridge (fit 49): qualified but not used, below the fit floor | G30: Rejected | H30: D2 | I30: 187 days old; this signal type counts for 90 days | J30: Dee Lim | K30: 187 | M30: Not run
A31: S01 | B31: 2027-04-20 | C31: 11 | D31: Tidewater Refining | E31: Inquiry or RFQ | F31: Tidewater (excluded): qualified but not used | G31: Rejected | H31: D2 | I31: 187 days old; this signal type counts for 90 days | J31: Hu Koh | K31: 187 | M31: Not run
A32: S02 | B32: 2026-10-20 | C32: 2 | D32: Apex Refining | E32: Inquiry or RFQ | F32: Fresh inquiry, weight 100: score 50, A | G32: Qualified | H32: Y2 | I32: Named in the file | J32: Kai Ong | K32: 10 | L32: 100 | M32: Not run
A33: S02 | B33: 2026-10-20 | C33: 3 | D33: Bayfront Refining | E33: Inquiry or RFQ | F33: 48 days: weight 70, score exactly 35: A (the cut-off is "at least 35") | G33: Qualified | H33: Y2 | I33: Named in the file | J33: Mia Tan | K33: 48 | L33: 70 | M33: Not run
A34: S02 | B34: 2026-10-20 | C34: 4 | D34: Coldwater Refining | E34: Inquiry or RFQ | F34: 49 days: weight 68.3, score 34.2: B | G34: Qualified | H34: Y2 | I34: Named in the file | J34: Oli Ng | K34: 49 | L34: 68.3 | M34: Not run
A35: S02 | B35: 2026-10-20 | C35: 5 | D35: Driftwood Refining | E35: Inquiry or RFQ | F35: 66 days: weight 40, score exactly 20: B | G35: Qualified | H35: Y2 | I35: Named in the file | J35: Quin Ong | K35: 66 | L35: 40 | M35: Not run
A36: S02 | B36: 2026-10-20 | C36: 6 | D36: Eastgate Refining | E36: Inquiry or RFQ | F36: 67 days: weight 38.3, score 19.2: C | G36: Qualified | H36: Y2 | I36: Named in the file | J36: Sam Sim | K36: 67 | L36: 38.3 | M36: Not run
A37: S03 | B37: 2026-10-20 | C37: 2 | D37: Apex Refining | E37: Inquiry or RFQ | F37: Apex Refining: inquiry | G37: Qualified | H37: Y2 | I37: Named in the file | J37: Kai Ong | K37: 5 | L37: 100 | M37: Not run
A38: S03 | B38: 2026-10-20 | C38: 3 | D38: Moorland Refining | E38: Inquiry or RFQ | F38: Moorland Refining: inquiry | G38: Qualified | H38: Y2 | I38: Named in the file | J38: Wes Goh | K38: 5 | L38: 100 | M38: Not run
A39: S03 | B39: 2026-10-20 | C39: 4 | D39: Pebblebrook Refining | E39: Inquiry or RFQ | F39: Pebblebrook Refining: inquiry | G39: Qualified | H39: Y2 | I39: Named in the file | J39: Xin Chua | K39: 5 | L39: 100 | M39: Not run
A40: S03 | B40: 2026-10-20 | C40: 5 | D40: Newhaven Petrochem | E40: Inquiry or RFQ | F40: Newhaven Petrochem: inquiry | G40: Qualified | H40: Y2 | I40: Named in the file | J40: Yan Lee | K40: 5 | L40: 100 | M40: Not run
A41: S03 | B41: 2026-10-20 | C41: 6 | D41: Oakridge Water | E41: Inquiry or RFQ | F41: Oakridge Water: inquiry | G41: Qualified | H41: Y2 | I41: Named in the file | J41: Zed Teo | K41: 5 | L41: 100 | M41: Not run
...

Sheet Scoring accounts
A1: File | B1: Score as of | C1: Account | D1: Fit (0-100) | E1: Timing (0-100) | F1: Score (0-100) | G1: Tier | H1: Qualified signals | I1: Confidence, or why not scored
A2: S01 | B2: 2026-10-20 | C2: Apex Refining | D2: 100 | E2: 50 | F2: 50 | G2: A | H2: 1 | I2: medium
A3: S01 | B3: 2026-10-20 | C3: Bayfront Refining | D3: 100 | E3: 50 | F3: 50 | G3: A | H3: 1 | I3: medium
A4: S01 | B4: 2026-10-20 | C4: Coldwater Refining | D4: 100 | E4: 40 | F4: 40 | G4: A | H4: 1 | I4: medium
A5: S01 | B5: 2026-10-20 | C5: Driftwood Refining | D5: 100 | E5: 30 | F5: 30 | G5: B | H5: 1 | I5: medium
A6: S01 | B6: 2026-10-20 | C6: Moorland Refining | D6: 94 | E6: 30 | F6: 28.2 | G6: B | H6: 1 | I6: medium
A7: S01 | B7: 2026-10-20 | C7: Juniper Fuels | D7: 50 | E7: 50 | F7: 25 | G7: B | H7: 1 | I7: low
A8: S01 | B8: 2026-10-20 | C8: Newhaven Petrochem | D8: 75 | E8: 22.5 | F8: 16.9 | G8: C | H8: 1 | I8: medium
A9: S01 | B9: 2026-10-20 | C9: Eastgate Refining | D9: 100 | E9: 15 | F9: 15 | G9: C | H9: 1 | I9: medium
A10: S01 | B10: 2026-10-20 | C10: Fairhaven Refining | D10: 100 | E10: 0 | F10: 0 | G10: Watch list | H10: 0 | I10: medium
A11: S01 | B11: 2026-10-20 | C11: Stonegate Refining | D11: 100 | E11: 0 | F11: 0 | G11: Watch list | H11: 0 | I11: medium
A12: S01 | B12: 2026-10-20 | C12: Larkspur Refining | D12: 97 | E12: 0 | F12: 0 | G12: Watch list | H12: 0 | I12: low
A13: S01 | B13: 2026-10-20 | C13: Rosewood Refining | D13: 97 | E13: 0 | F13: 0 | G13: Watch list | H13: 0 | I13: low
... A16: S01 | B16: 2026-10-20 | C16: Oakridge Water | D16: 60 | E16: 0 | F16: 0 | G16: Watch list | H16: 0 | I16: medium
A17: S01 | B17: 2026-10-20 | C17: Kingsbridge Fuels | D17: 49 | G17: Below fit floor | H17: 0
A18: S01 | B18: 2026-10-20 | C18: Tidewater Refining | G18: Excluded | H18: 0 | I18: Outside the pilot region (Australia)
A19: S01 | B19: 2026-12-20 | C19: Bayfront Refining | D19: 100 | E19: 50 | F19: 50 | G19: A | H19: 1 | I19: medium
A20: S01 | B20: 2026-12-20 | C20: Coldwater Refining | D20: 100 | E20: 38.4 | F20: 38.4 | G20: A | H20: 1 | I20: medium
A21: S01 | B21: 2026-12-20 | C21: Moorland Refining | D21: 94 | E21: 29.7 | F21: 27.9 | G21: B | H21: 1 | I21: medium
A22: S01 | B22: 2026-12-20 | C22: Driftwood Refining | D22: 100 | E22: 21.8 | F22: 21.8 | G22: B | H22: 1 | I22: medium
A23: S01 | B23: 2026-12-20 | C23: Apex Refining | D23: 100 | E23: 20 | F23: 20 | G23: B | H23: 1 | I23: medium
A24: S01 | B24: 2026-12-20 | C24: Juniper Fuels | D24: 50 | E24: 20 | F24: 10 | G24: C | H24: 1 | I24: low
A25: S01 | B25: 2026-12-20 | C25: Newhaven Petrochem | D25: 75 | E25: 12.2 | F25: 9.2 | G25: C | H25: 1 | I25: medium
A26: S01 | B26: 2026-12-20 | C26: Eastgate Refining | D26: 100 | E26: 0 | F26: 0 | G26: Watch list | H26: 0 | I26: medium
A27: S01 | B27: 2026-12-20 | C27: Fairhaven Refining | D27: 100 | E27: 0 | F27: 0 | G27: Watch list | H27: 0 | I27: medium
A28: S01 | B28: 2026-12-20 | C28: Stonegate Refining | D28: 100 | E28: 0 | F28: 0 | G28: Watch list | H28: 0 | I28: medium
A29: S01 | B29: 2026-12-20 | C29: Larkspur Refining | D29: 97 | E29: 0 | F29: 0 | G29: Watch list | H29: 0 | I29: low
A30: S01 | B30: 2026-12-20 | C30: Rosewood Refining | D30: 97 | E30: 0 | F30: 0 | G30: Watch list | H30: 0 | I30: low
... A33: S01 | B33: 2026-12-20 | C33: Oakridge Water | D33: 60 | E33: 0 | F33: 0 | G33: Watch list | H33: 0 | I33: medium
A34: S01 | B34: 2026-12-20 | C34: Kingsbridge Fuels | D34: 49 | G34: Below fit floor | H34: 0
A35: S01 | B35: 2026-12-20 | C35: Tidewater Refining | G35: Excluded | H35: 0 | I35: Outside the pilot region (Australia)
A36: S01 | B36: 2027-04-20 | C36: Bayfront Refining | D36: 100 | E36: 50 | F36: 50 | G36: A | H36: 1 | I36: medium
A37: S01 | B37: 2027-04-20 | C37: Coldwater Refining | D37: 100 | E37: 20.8 | F37: 20.8 | G37: B | H37: 1 | I37: medium
A38: S01 | B38: 2027-04-20 | C38: Apex Refining | D38: 100 | E38: 0 | F38: 0 | G38: Watch list | H38: 0 | I38: medium
A39: S01 | B39: 2027-04-20 | C39: Driftwood Refining | D39: 100 | E39: 0 | F39: 0 | G39: Watch list | H39: 0 | I39: medium
A40: S01 | B40: 2027-04-20 | C40: Eastgate Refining | D40: 100 | E40: 0 | F40: 0 | G40: Watch list | H40: 0 | I40: medium
A41: S01 | B41: 2027-04-20 | C41: Fairhaven Refining | D41: 100 | E41: 0 | F41: 0 | G41: Watch list | H41: 0 | I41: medium
A42: S01 | B42: 2027-04-20 | C42: Stonegate Refining | D42: 100 | E42: 0 | F42: 0 | G42: Watch list | H42: 0 | I42: medium
A43: S01 | B43: 2027-04-20 | C43: Larkspur Refining | D43: 97 | E43: 0 | F43: 0 | G43: Watch list | H43: 0 | I43: low
A44: S01 | B44: 2027-04-20 | C44: Rosewood Refining | D44: 97 | E44: 0 | F44: 0 | G44: Watch list | H44: 0 | I44: low
...

Sheet Summary
A1: Folder | B1: Files | C1: Not run | D1: Pass | E1: Fail | F1: Blocked | G1: Not in scope
A2: 1-Prospecting | B2: =COUNTIF(Files!$B:$B,A2) | C2: =COUNTIFS(Files!$B:$B,$A2,Files!$J:$J,"Not run") | D2: =COUNTIFS(Files!$B:$B,$A2,Files!$J:$J,"Pass") | E2: =COUNTIFS(Files!$B:$B,$A2,Files!$J:$J,"Fail") | F2: =COUNTIFS(Files!$B:$B,$A2,Files!$J:$J,"Blocked") | G2: =COUNTIFS(Files!$B:$B,$A2,Files!$J:$J,"Not in scope")
A3: 2-Account-Scoring | B3: =COUNTIF(Files!$B:$B,A3) | C3: =COUNTIFS(Files!$B:$B,$A3,Files!$J:$J,"Not run") | D3: =COUNTIFS(Files!$B:$B,$A3,Files!$J:$J,"Pass") | E3: =COUNTIFS(Files!$B:$B,$A3,Files!$J:$J,"Fail") | F3: =COUNTIFS(Files!$B:$B,$A3,Files!$J:$J,"Blocked") | G3: =COUNTIFS(Files!$B:$B,$A3,Files!$J:$J,"Not in scope")
A4: 3-Signal-rules | B4: =COUNTIF(Files!$B:$B,A4) | C4: =COUNTIFS(Files!$B:$B,$A4,Files!$J:$J,"Not run") | D4: =COUNTIFS(Files!$B:$B,$A4,Files!$J:$J,"Pass") | E4: =COUNTIFS(Files!$B:$B,$A4,Files!$J:$J,"Fail") | F4: =COUNTIFS(Files!$B:$B,$A4,Files!$J:$J,"Blocked") | G4: =COUNTIFS(Files!$B:$B,$A4,Files!$J:$J,"Not in scope")
A5: 4-Micro-segments-and-Review | B5: =COUNTIF(Files!$B:$B,A5) | C5: =COUNTIFS(Files!$B:$B,$A5,Files!$J:$J,"Not run") | D5: =COUNTIFS(Files!$B:$B,$A5,Files!$J:$J,"Pass") | E5: =COUNTIFS(Files!$B:$B,$A5,Files!$J:$J,"Fail") | F5: =COUNTIFS(Files!$B:$B,$A5,Files!$J:$J,"Blocked") | G5: =COUNTIFS(Files!$B:$B,$A5,Files!$J:$J,"Not in scope")
A6: Total | B6: =SUM(B2:B5) | C6: =SUM(C2:C5) | D6: =SUM(D2:D5) | E6: =SUM(E2:E5) | F6: =SUM(F2:F5) | G6: =SUM(G2:G5)
